Workbook

Sheet Guide de notation
A1: GRILLE DE NOTATION — Assistant IA LRGP
A2: Chaque critère est noté de 1 à 5 — 5 = parfait, 1 = incorrect
A3: Critère | B3: Description | C3: Barème
A4: Exactitude factuelle | B4: Les valeurs numériques sont-elles correctes ? Les faits scientifiques sont-ils justes ? 5 = toutes les valeurs exactes 3 = quelques erreurs mineures 1 = valeurs incorrectes ou inventées | C4: 1 = Faux 2 = Insuffisant 3 = Partiel 4 = Bon 5 = Parfait
A5: Rigueur de la démarche | B5: Les étapes de calcul sont-elles correctes et complètes ? La démarche est-elle reproductible ? 5 = toutes les étapes détaillées et correctes 3 = étapes présentes mais incomplètes 1 = démarche absente ou erronée | C5: 1 = Absente 2 = Insuffisant 3 = Partielle 4 = Bonne 5 = Complète
A6: Pertinence physique | B6: Les unités sont-elles correctes à chaque étape ? Les ordres de grandeur sont-ils cohérents ? 5 = unités et ordres de grandeur parfaits 3 = quelques erreurs d'unités 1 = erreurs d'unités majeures | C6: 1 = Faux 2 = Insuffisant 3 = Partiel 4 = Bon 5 = Parfait
A7: Clarté pédagogique | B7: La réponse est-elle bien structurée et lisible ? Un étudiant M2 comprendrait-il ? 5 = claire, structurée, exemplaire 3 = compréhensible mais améliorable 1 = confuse ou illisible | C7: 1 = Confuse 2 = Insuffisant 3 = Acceptable 4 = Claire 5 = Exemplaire
A8: Citation des sources | B8: Les sources sont-elles citées ? Les citations sont-elles précises et correctes ? 5 = toutes les sources citées correctement 3 = sources partiellement citées 1 = aucune source citée | C8: 1 = Absente 2 = Insuffisant 3 = Partielle 4 = Bonne 5 = Complète
A10: PROTOCOLE DE CALIBRATION (30 min)
A11: 1. Les deux annotateurs notent les 5 premières fiches ensemble à voix haute
A12: 2. Discussion des désaccords pour aligner la compréhension des critères
A13: 3. Notation indépendante des 36 fiches restantes sans se concerter
A14: 4. Calcul du κ Cohen après notation complète (script compute_kappa.py)
A15: 5. κ > 0.6 → accord satisfaisant | κ < 0.4 → recalibrer

Sheet Annotateur 1
A1: ÉVALUATION HUMAINE — ANNOTATEUR 1 — Baseline RAG Qwen3.5:9b
A2: Remplir les colonnes G à L avec des notes de 1 à 5 — Colonne L calculée automatiquement — Ne pas consulter l'autre annotateur
A3: ID | B3: Type | C3: Niveau | D3: Question | E3: Réponse modèle | F3: Référence | G3: Exactitude factuelle | H3: Rigueur démarche | I3: Pertinence physique | J3: Clarté pédagogique | K3: Citation sources | L3: Score global | M3: Commentaire
A4: Q060 | B4: FACTUEL | C4: N2 | D4: D'après Huang et al., cités dans l'étude d'Aspen Hysys, quelle est la plage de valeurs recommandées pour le rapport de pression (pressure ratio) afin que les procédés membranaires soient économiquement viables ? | E4: D'après les documents fournis, spécifiquement le Document 1, la plage de valeurs recommandée pour le rapport de pression (pressure ratio) afin que les procédés membranaires soient économiquement viables est de 5 à 15. Cette recommandation est basée sur les travaux de Huang et al. cités dans le contexte de la modélisation exportée vers Aspen Hysys. Détails de la réponse : * Plage de pression recommandée : $5 \leq \theta \leq 15$ * Justification : Les auteurs indiquent que ce rapport est optimal pour assurer la viabilité économique du procédé. Au-delà de cette valeur, la consommation d'énergie pour les compresseurs et les pompes à vide devient trop importante. * Source : [Source: 36012f7a-6cac-eb11-94d7-0050568d0279_Thesis-Ehsan Soroodan Miandoab-Unimel...ersion | Page: 0] Extrait pertinent du contexte : > "Huang et al. [67] argued that the optimum pressure ratio should be in the range of 5-15 in order for membrane processes to be economically viable. This pressure ratio range is adopted here as the basis for the driving force across the membrane." | F4: Le rapport de pression optimal (défini comme la pression d'alimentation divisée par la pression de perméat) doit se situer dans la plage de 5 à 15 (5-15) pour assurer la viabilité économique du procédé. | L4: =IFERROR(AVERAGE(G4:K4),"")
A5: Q078 | B5: CALCUL | C5: N3 | D5: Dans un contacteur à fibres creuses modélisé par l'approche des résistances en série, sachant que la résistance globale de transfert de matière est l'inverse du coefficient global (1/K), calculer cette résistance globale en s/m si le coefficient global K est de 4 * 10^-5 m/s. | E5: # 1. Identification de l'équation ou corrélation pertinente Selon le contexte fourni, la résistance globale de transfert de matière est définie comme l'inverse du coefficient global de transfert de matière. * Relation fondamentale : La résistance globale $R$ est exprimée par l'inverse du coefficient global $K$. * Équation : $$ R = \frac{1}{K} $$ * Source de la relation : [Source: Elsevier Encyclopedia Membrane Contactors Chabanon & Favre] * Unité du coefficient $K$ : Le coefficient global de transfert de matière $K$ est défini avec l'unité $[m/s]$ dans les documents du laboratoire. * Source de l'unité : [Source: 2011 NGUYEN_FAVRE Contacteurs à membranes denses pour les procédés d’absorption gaz-liquide intensifiés application à la capture du CO2 en post combustion] # 2. Liste des données numériques disponibles * Coefficient global de transfert de matière ($K$) : $4 \times 10^{-5} \, \text{m/s}$ (donné dans l'énoncé de la question). * Unité de $K$ : $\text{m/s}$ (confirmé par les documents). * Unité cible de la résistance ($R$) : $\text{s/m}$ (inverse de $\text{m/s}$). # 3. Calcul étape par étape Le calcul consiste à inverser la valeur numérique du coefficient $K$. Étape 1 : Écrire l'expression de la résistance $$ R = \frac{1}{K} $$ Étape 2 : Substituer la valeur de $K$ $$ R = \frac{1}{4 \times 10^{-5} \, \text{m/s}} $$ Étape 3 : Effectuer la division numérique $$ \frac{1}{4} = 0.25 $$ $$ \frac{1}{10^{-5}} = 10^{5} $$ $$ R = 0.25 \times 10^{5} \, \text{s/m} $$ Étape 4 : Mettre sous forme scientifique standard $$ R = 2.5 \times 10^{4} \, \text{s/m} $$ Étape 5 : Convertir en notation décimale $$ R = 25\,000 \, \text{s/m} $$ # 4. Vérification de la cohérence dimensionnelle * Dimension de $K$ : $[L] \cdot [T]^{-1}$ (mètre par seconde). * Dimension de $R$ : $1 / ([L] \cdot [T]^{-1}) = [T] \cdot [L]^{-1}$ (seconde par mètre). * Vérification : L'unité obtenue est bien $\text{s/m}$, ce qui correspond à l'unité demandée pour la résistanc | F5: La résistance globale est 1 / (4 * 10^-5) = 25000 s/m. | L5: =IFERROR(AVERAGE(G5:K5),"")
A6: Q044 | B6: FACTUEL | C6: N2 | D6: Outre la valorisation du biogaz, pour quelles autres applications la combinaison d'une haute sélectivité, d'une perméance adéquate et d'une bonne stabilité à long terme rend-elle les membranes nanocomposites prometteuses ? | E6: D'après les documents fournis, la combinaison d'une haute sélectivité, d'une perméance adéquate et d'une excellente stabilité à long terme rend les membranes nanocomposites prometteuses pour les applications suivantes, à l'exclusion de la valorisation du biogaz : 1. Le sweetening du gaz naturel (natural gas sweetening) : Cette application est citée dans le contexte comme l'un des domaines où la séparation efficace du CO₂/CH₄ est requise [Source: Advanced_Two_Stage_Nanocomposite_Membran]. 2. La purification du gaz de décharge (landfill gas purification) : Ce procédé est également listé comme une application bénéficiant de ces propriétés membranaires [Source: Advanced_Two_Stage_Nanocomposite_Membran]. 3. La capture directe de gaz à effet de serre (direct air capture of greenhouse gases) : Ce domaine est mentionné comme une application réelle pour laquelle les résultats de perméation sont cruciaux [Source: Advanced_Two_Stage_Nanocomposite_Membran]. Ces informations sont extraites des documents décrivant les performances des membranes nanocomposites dans des conditions d'exploitation réalistes [Source: Advanced_Two_Stage_Nanocomposite_Membran]. | F6: Ces membranes sont également très prometteuses pour l'adoucissement du gaz naturel (natural gas sweetening) et pour la purification des gaz de décharge (landfill gas purification). | L6: =IFERROR(AVERAGE(G6:K6),"")
A7: Q008 | B7: CALCUL | C7: N2 | D7: Adsorption batch : 1 m³ eau usée, C₀=0,21 kg phénol/m³, 1,4 kg charbon actif (m=0,199×c^0,229). Trouver m et c à l'équilibre et le % phénol extrait. | F7: Intersection isotherme et bilan 1,4m+c=0,21 : m=0,106 kg/kg, c=0,062 kg/m³. Phénol extrait=70,47%. | L7: =IFERROR(AVERAGE(G7:K7),"")
A8: Q020 | B8: FACTUEL | C8: N2 | D8: Sur quel principe repose le procédé de perméation gazeuse et quelles sont les configurations de pression typiques pour l'opérer ? | E8: # Principe du procédé de perméation gazeuse Le procédé de perméation gazeuse repose sur le principe de la mise en contact continu d'un flux d'alimentation (mélange à séparer) avec un matériau sélectif, appelé membrane, inséré dans un module [Source: 10 Chapitre Membranes Polycopié S6 ENSIC | Page: 0]. L'efficacité de l'opération dépend de trois facteurs principaux : 1. Les performances du matériau membranaire (perméabilité et permélectivité). 2. La force motrice appliquée (différence de pression partielle de part et d'autre de la membrane). 3. L'agencement des flux dans le module [Source: 10 Chapitre Membranes Polycopié S6 ENSIC | Page: 0]. Le processus sépare le flux d'alimentation en deux composantes à la sortie : * Le rétentat (côté haute pression) : partie n'ayant pas traversé la membrane, enrichie en composés moins perméables. * Le perméat (côté basse pression) : fraction ayant traversé la membrane, enrichie en composés plus perméables [Source: 10 Chapitre Membranes Polycopié S6 ENSIC | Page: 0]. # Configurations de pression typiques Pour appliquer la force motrice nécessaire au transfert de matière à travers la membrane, plusieurs configurations de pression peuvent être utilisées [Source: 10 Chapitre Membranes Polycopié S6 ENSIC | Page: 0] : 1. Compression en amont : Application d'une compression sur le flux d'alimentation en amont du matériau membranaire. 2. Tirage au vide en aval : Application d'un tirage au vide sur la partie aval du matériau membranaire. 3. Balayage (Sweep) : Dilution par balayage d'un gaz inerte et imperméable du côté perméat [Source: 10 Chapitre Membranes Polycopié S6 ENSIC | Page: 0]. Le procédé nécessite également un système de compression pour la force motrice, ce qui permet une grande liberté sur le design du module [Source: DDOC_T_2017_0020_PFISTER | Page: 0]. | F8: Repose sur une différence de perméabilité entre les composés. Force motrice créée par : compression amont, mise sous vide aval, ou combinaison des deux. | L8: =IFERROR(AVERAGE(G8:K8),"")
A9: Q032 | B9: FACTUEL | C9: N2 | D9: Quel est l'objectif principal de l'étude publiée concernant les stratégies de modélisation pour le captage du CO2 ? | E9: D'après les documents fournis dans le contexte, l'objectif principal de l'étude est le suivant : Objectif principal : Réaliser une analyse comparative critique des stratégies de modélisation pour le captage du CO₂ par absorption dans l'MEA (Monoéthanolamine) grâce aux contacteurs membranaires. Justification et Source : Cette information est explicitement indiquée dans l'introduction de chaque document fourni, qui stipulent que : *"This study intended to achieve a critical comparative analysis of modeling strategies for CO 2 capture by absorption in MEA thanks to membrane contactors."* En français, cela se traduit par : *"Cette étude visait à réaliser une analyse comparative critique des stratégies de modélisation pour le captage du CO2 par absorption dans l'MEA grâce aux contacteurs membranaires."* [Source: CES 2012 revised manuscript_docx] *Note : Cette formulation est identique dans les cinq documents fournis (Documents 1 à 5), confirmant la cohérence de l'objectif énoncé.* | F9: L'objectif principal de l'étude est de réaliser une analyse comparative critique des différentes stratégies de modélisation pour le captage du CO2 par absorption dans la MEA à l'aide de contacteurs membranaires. | L9: =IFERROR(AVERAGE(G9:K9),"")
A10: Q074 | B10: FACTUEL | C10: N2 | D10: D'après les articles de Chabanon et al. (2012, 2013), quel est l'avantage principal d'utiliser un coefficient global de transfert de matière constant (Kov) pour modéliser le transfert dans les contacteurs membranaires ? | E10: D'après les documents fournis, l'avantage principal d'utiliser un coefficient global de transfert de matière constant ($K_{OV}$) pour modéliser le transfert dans les contacteurs membranaires est la simplification de l'analyse et l'évaluation rapide des performances. Voici les points clés identifiés dans les textes : 1. Simplification du modèle : Cette approche permet d'inclure les différents mécanismes de transfert de matière dans un seul paramètre global ($K_{OV}$). C'est également décrite comme l'approche la plus simple disponible [Source: CES 2012 revised manuscript_docx | Page: 0], [Source: Elsevier Encyclopedia Membrane Contactors Chabanon & Favre | Page: 0]. 2. Évaluation des performances : L'utilisation de ce paramètre unique permet d'évaluer rapidement et facilement les performances du procédé [Source: CES 2012 revised manuscript_docx | Page: 0], [Source: Chabanon_2013_CES | Page: 0]. 3. Comparabilité : Connaître la surface interfaciale gaz-liquide ($a$) et le coefficient $K_{OV}$ permet d'obtenir facilement la performance $K_{OV} \cdot a$ pour la comparer avec d'autres technologies [Source: Elsevier Encyclopedia Membrane Contactors Chabanon & Favre | Page: 0]. En résumé, l'avantage réside dans la capacité à regrouper la complexité des mécanismes de transfert en un paramètre unique ($K_{OV}$), facilitant ainsi l'analyse et la comparaison des procédés [Source: CES 2012 revised manuscript_docx | Page: 0]. | F10: L'avantage principal est d'inclure les différents mécanismes de transfert de matière dans un seul paramètre global, ce qui permet d'évaluer les performances du procédé de manière rapide et facile. | L10: =IFERROR(AVERAGE(G10:K10),"")
A11: Q003 | B11: FACTUEL | C11: N1 | D11: Les techniques de séparation membranaires mettent en oeuvre des systèmes polyphasés constitués par quels éléments ? | E11: D'après les documents fournis, voici la réponse structurée concernant la constitution des systèmes polyphasés en séparation membranaire : # 1. Référence au concept de système polyphasé Le Document 1 [Source: fndae14] énonce explicitement que : > « La principale caractéristique des techniques de séparation membranaires est de mettre en œuvre des systèmes polyphasés constitués par : » Cependant, l'extrait fourni se termine immédiatement après le deux-points, sans énumérer la liste des éléments constitutifs spécifiques dans le texte disponible. # 2. Informations disponibles sur la constitution du système Bien que la liste complète ne soit pas terminée dans le Document 1, les Documents 3, 4 et 5 décrivent les éléments structuraux et les phases impliqués dans ces systèmes : * Structure de la membrane : * Les membranes sont décrites comme des membranes denses (non poreuses) pour la séparation [Source: Thèse CIFRE Simon - 3 mars 2019]. * Elles possèdent une couche dense de séparation d'une épaisseur comprise entre 0,1 et quelques microns [Source: PDMS DDOC_T_2016_0183_BERGER]. * Cette couche dense est supportée par une couche poreuse dont le rôle est purement mécanique [Source: DOC_BERGER Etude de l’intégration des séparations membranaires Biogaz]. * Si les deux couches sont du même polymère, c'est une membrane asymétrique ; sinon, c'est une membrane composite [Source: PDMS DDOC_T_2016_0183_BERGER]. * Phases du système : * Le mécanisme de transport implique la sorption du perméant dans la membrane, la perméation par diffusion à travers la membrane, et la désorption du perméant à la | F11: 1) Le fluide à traiter, 2) Le fluide traité (solution à dépolluer, eau à dessaler...), 3) La membrane. | L11: =IFERROR(AVERAGE(G11:K11),"")
A12: Q093 | B12: CALCUL | C12: N2 | D12: Dans la simulation d'un système couplé absorption/stripping (désorption) (Doc 3 et 6), le débit total de CO2 absorbé dans le contacteur à fibres creuses principal est de 500 mol/h. Lors de l'étape de stripping (stripping step), l'efficacité de désorption limite la récupération. Si 85 % du CO2 préalablement absorbé est effectivement désorbé et récupéré en phase gaz, et que l'aire membranaire dédiée au module de désorption est de 20 m2, calculez le flux molaire moyen de CO2 désorbé (en mol/(m2.h)). | E12: Avertissement concernant les documents : Il est important de noter que le Document 6 mentionné dans la question n'est pas inclus dans le corpus de documents fourni (seuls les Documents 1 à 5 sont disponibles). Par conséquent, les informations spécifiques à ce document ne peuvent pas être vérifiées ou utilisées. Contexte du procédé : Les documents fournis confirment la description d'un système d'absorption/désorption couplée utilisant des modules à fibres creuses (HFMC) [Source: Thesis_Qazi_2020 | Page: 0]. Le Document 4 décrit le procédé couplé où l'absorption et la désorption sont réalisées en un seul cycle de recirculation [Source: Thesis_Qazi_2020 | Page: 0]. Le Document 5 confirme cette configuration avec un premier HFMC pour l'absorption et un deuxième pour la désorption par balayage d'azote [Source: Thesis_Qazi_2020 | Page: 0]. 1. Identification de l'équation pertinente : Les documents fournis décrivent les performances et les profils de flux [Source: 1-s2.0-S1383586617315381-main | Page: 0], mais ne définissent pas explicitement l'équation fondamentale du flux molaire. Cependant, conformément aux principes de base du génie des procédés membranaires (flux membranaire), le flux molaire moyen ($J$) est défini comme le rapport entre le débit molaire total ($\dot{n}$) et l'aire membranaire ($A$). L'équation utilisée est : $$ J = \frac{\dot{n}_{\text{désorbé}}}{A} $$ 2. Liste des données numériques : * Débit total de CO₂ absorbé ($\dot{n}_{\text{absorbé}}$) : $500 \text{ mol/h}$ * Efficacité de désorption ($\eta$) : $85\%$ ou $0.85$ * Aire membranaire dédiée au module de désorption ($A$) : $20 \text{ m}^2$ 3. Calcul étape par étape : * Étape 1 : Calcul du débit molaire de CO₂ désorbé ($\dot{n}_{\text{désorbé}}$) Le débit de CO₂ récupéré est une fraction du débit absorbé. $$ \dot{n}_{\text{désorbé}} = \dot{n}_{\text{absorbé}} \times \eta $$ $$ \dot{n}_{\text{désorbé}} = 500 \text{ mol/h} \times 0.85 $$ $$ \dot{n}_{\text{désorbé}} = 425 | F12: La quantité de CO2 désorbée est de 500 mol/h * 0,85 = 425 mol/h. Le flux molaire moyen rapporté à l'aire membranaire est donc Flux = 425 mol/h / 20 m2 = 21,25 mol/(m2.h). | L12: =IFERROR(AVERAGE(G12:K12),"")
A13: Q087 | B13: CALCUL | C13: N3 | D13: Une unité de purification membranaire de gaz naturel possède deux étages pour minimiser les pertes. L'alimentation est de 100 mol/s avec 15% de CO2 et 85% de CH4. Le premier étage sépare le gaz en un rétentat R1 contenant 70% de la quantité initiale de CH4 à une pureté de 95%, et un perméat P1. Calculez le débit total (en mol/s) du perméat P1 qui sera envoyé au deuxième étage, ainsi que sa concentration molaire en CH4 (en %). | F13: CH4 entrant total = 100 * 0,85 = 85 mol/s. CH4 dans R1 = 0,70 * 85 = 59,5 mol/s. Débit total de R1 = 59,5 / 0,95 = 62,63 mol/s. Par bilan de matière global sur le premier étage : Débit de P1 = Alimentation - R1 = 100 - 62,63 = 37,37 mol/s. La quantité de CH4 dans P1 = CH4 entrant - CH4 dans R1 = 85 - 59,5 = 25,5 mol/s. Concentration de CH4 dans P1 = (25,5 / 37,37) * 100 = 68,24 %. | L13: =IFERROR(AVERAGE(G13:K13),"")
A14: Q097 | B14: CALCUL | C14: N2 | D14: Le document 1 mentionne un 'Coefficient de transfert de matière global rapporté au volume du contacteur', notons-le Kv (souvent exprimé comme K*a). Sachant que le coefficient K s'exprime en m/s (Doc 11), si un contacteur a un coefficient global K = 4.10^-4 m/s et une aire spécifique a = 2500 m2/m3, calculez ce coefficient volumique global de transfert Kv en s^-1. | E14: # 1. Identification de l'équation pertinente Selon le Document 4, le taux de transfert volumique (noté ici $K_v$ ou $K \cdot a$) est défini comme le produit du coefficient global de transfert de matière $K$ et de l'aire interfaciale spécifique $a$. La relation est donnée par : $$ K_v = K \cdot a $$ Cette relation est explicitement décrite dans le document comme suit : "Le taux de transfert K.a, exprimé en s -1 , englobe le coefficient global de transfert de matière K [m/s] et l'aire interfaciale a..." [Source: 2011 NGUYEN_FAVRE Contacteurs à membranes denses pour les procédés d’absorption gaz-liquide intensifiés application à la capture du CO2 en post combustion]. # 2. Liste des données numériques Les valeurs fournies dans l'énoncé de la question sont : * Coefficient global de transfert de matière : $K = 4 \times 10^{-4} \, \text{m/s}$ * Aire interfaciale spécifique : $a = 2500 \, \text{m}^2/\text{m}^3$ Les unités sont confirmées par les documents : * $K$ en $\text{m/s}$ [Source: 2011 NGUYEN_FAVRE...] * $a$ en $\text{m}^2/\text{m}^3$ [Source: 2011 NGUYEN_FAVRE...] # 3. Calcul étape par étape Nous appliquons la relation identifiée à l'étape 1 : $$ K_v = K \times a $$ Substitution des valeurs : $$ K_v = (4 \times 10^{-4} \, \text{m/s}) \times (2500 \, \text{m}^2/\text{m}^3) $$ Calcul numérique : $$ 4 \times 2500 = 10\,000 $$ $$ 10\,000 \times 10^{-4} = 1 $$ # 4. Vérification de la cohérence dimensionnelle Analyse des unités : $$ [\text{m/s}] \times [\text{m}^2/\text{m}^3] = \frac{\text{m} \cdot \text{m}^2}{\text{s} \cdot \text{m}^3} = \frac{\text{m}^3}{\text{s} \cdot \text{m}^3} = \frac{1}{\text{s}} = \text{s}^{-1} $$ Le résultat obtenu est bien exprimé en $\text{s}^{-1}$, ce qui correspond à la définition du taux de transfert donnée dans le Document 4 [Source: 2011 NGUYEN_FAVRE Contacteurs à membranes denses pour les procédés d’absorption gaz-liquide intensifiés application à la capture du CO2 en post combustion]. # 5. Résultat final Le coe | F14: Le coefficient volumique se calcule par Kv = K * a = 4.10^-4 m/s * 2500 m2/m3 = 1 s^-1. | L14: =IFERROR(AVERAGE(G14:K14),"")
A15: Q006 | B15: CALCUL | C15: N4 | D15: Données Langmuir : P=[10,30,40,80,120] mm Hg, V=[117,64;119,20;119,40;119,70;119,80] ml/g. Vérifier graphiquement la loi de Langmuir et déterminer Vm, b et la surface spécifique. | F15: Tracer P/V=f(P) → droite y=0,0083x+0,0017 (R²=1) → Langmuir vérifié. Vm=120,48 ml/g, b=4,88 mm Hg⁻¹. S≈648 m²/g. | L15: =IFERROR(AVERAGE(G15:K15),"")
A16: Q030 | B16: FACTUEL | C16: N1 | D16: Quelle est la fraction massique de la solution de MEA (Monoéthanolamine) utilisée dans le module de contacteur membranaire lors de l'absorption du solvant, selon les travaux de Scholes ? | E16: Selon les documents fournis, spécifiquement ceux associés aux travaux de Scholes, la fraction massique de la solution de MEA (Monoéthanolamine) utilisée dans le module de contacteur membranaire lors de l'absorption du solvant est de 30 % en masse (30 wt%). Cette information est extraite de la légende de la Figure 6 présente dans les documents liés à Scholes, qui précise : *"in the 30 wt% MEA solution exiting the membrane contactor module undertaking solvent absorption"* [Source: 2020 Scholes_Contactor_Pilot_plant_paper_revised_2_240115_165610]. Détails de l'information : * Concentration : 30 wt% (30 % en masse). * Contexte : Solution de MEA sortant du module de contacteur membranaire lors de l'absorption du CO₂. * Source : Document 3 (et Document 4 qui contient la même légende). Aucun calcul n'est nécessaire car la valeur est explicitement indiquée dans la description du document. | F16: La fraction massique de la solution de MEA utilisée est de 30 % en poids (30 wt%). | L16: =IFERROR(AVERAGE(G16:K16),"")
A17: Q082 | B17: CALCUL | C17: N3 | D17: Une unité de purification de gaz naturel vise à éliminer le CO2 pour atteindre la norme de 98 % massique en CH4, profitant du fait que le CH4 est le composé 'lent'. Le flux d'alimentation sous pression est de 5000 kg/h avec 90% de CH4 et 10% de CO2. Le rétentat obtenu atteint exactement 98% massique de CH4. En supposant que le débit de perte de CH4 dans le perméat est de 50 kg/h, quel est le débit total du rétentat (en kg/h) et quel est le débit de CO2 éliminé dans le perméat (en kg/h) ? | F17: Débit de CH4 entrant = 5000 * 0,90 = 4500 kg/h. Débit de CH4 dans le rétentat = 4500 - 50 = 4450 kg/h. Comme le rétentat contient 98% de CH4, le débit total du rétentat = 4450 / 0,98 = 4540,82 kg/h. Le débit de CO2 dans le rétentat = 4540,82 - 4450 = 90,82 kg/h. Le débit de CO2 entrant = 5000 * 0,10 = 500 kg/h. Le CO2 éliminé dans le perméat = 500 - 90,82 = 409,18 kg/h. | L17: =IFERROR(AVERAGE(G17:K17),"")
A18: Q064 | B18: FACTUEL | C18: N1 | D18: Quelle est l'unité la plus fréquemment utilisée pour exprimer la perméabilité des membranes polymères denses, et à quelle valeur correspond-elle dans le système d'unités associant le cm³(STP), le cm, la seconde et le cmHg ? | E18: D'après les documents fournis, voici la réponse structurée concernant l'unité de perméabilité des membranes polymères denses : # 1. L'unité la plus fréquemment utilisée L'unité la plus fréquemment employée pour exprimer la perméabilité des polymères est le Barrer. * Source : [Source: 42493210-j2810-1] # 2. Valeur correspondante dans le système d'unités demandé Le Barrer correspond à la valeur suivante dans le système associant le cm³(STP), le cm, la seconde et le cmHg : $$ 1 \text{ Barrer} = 10^{-10} \, \text{cm}^3(\text{STP}) \cdot \text{cm} \cdot \text{cm}^{-2} \cdot \text{s}^{-1} \cdot \text{cmHg}^{-1} $$ * Source : [Source: Thèse CIFRE Simon - 3 mars 2019] * Confirmation : [Source: Polymer_Membranes_for_Gas_Separation] # 3. Détails et hypothèses * Définition de la perméabilité : La perméabilité ($P$) est définie comme le produit de la solubilité ($S$) et de la diffusion ($D$) ($P = S \cdot D$) [Source: 42493210-j2810-1]. * Unité de pression : La différence de pression partielle ($\Delta p_i$) est exprimée en cmHg [Source: Thèse CIFRE Simon - 3 mars 2019]. * Unité de volume : Le débit volumique est ramené aux conditions standards (STP/CSTP) [Source: Thèse CIFRE Simon - 3 mars 2019]. * Note sur la notation : Bien que le Document 1 mentionne une notation avec un "N" devant le cm³ ($10^{-10} \text{Ncm}^3$), les Documents 4 et 5 clarifient la définition standard sans ce préfixe, utilisant explicitement le cm³(STP) et le cmHg⁻¹. Référence complète des sources utilisées : 1. [Source: 42493210-j2810-1] pour l'identification de l'unité "Barrer" comme la plus fréquente. 2. [Source: Thèse CIFRE Simon - 3 mars 2019] pour la définition numérique de 1 Barrer ($10^{-10} \text{cm}^3(\text{STP}) \text{cm} \cdot \text{cm}^{-2} \cdot \text{s}^{-1} \cdot \text{cmHg}^{-1}$). 3. [Source: Polymer_Membranes_for_Gas_Separation] pour la confirmation des unités Barrer et GPU. | F18: L'unité la plus fréquemment employée est le Barrer. 1 Barrer correspond à 10^(-10) cm³(STP) · cm / (s · cm² · cmHg), ce qui équivaut à 10^(-10) Ncm³ · cm · s^(-1) · cm^(-2) · cmHg^(-1). | L18: =IFERROR(AVERAGE(G18:K18),"")
A19: Q054 | B19: FACTUEL | C19: N2 | D19: Selon les mots-clés de l'étude de Lee (2022), quel processus membranaire, constituant la phase inverse du captage, fait l'objet d'une modélisation théorique ? | E19: D'après les documents fournis dans le contexte, il n'est pas possible de répondre à votre question. Explication : Les documents disponibles (Document 1 et Document 2) ne contiennent aucune référence à une étude de Lee (2022). Le Document 1 liste exclusivement des références liées au laboratoire LRGP et à EDF, notamment : - Thèses et rapports de T. Neveux (2013, 2014, 2015, 2019, 2020, 2022) [Source: EDF_2022-capitalisation-RO_Bore]. - Articles de D.R. Albarracin-Zaidiza et al. (2015) [Source: EDF_2022-capitalisation-RO_Bore]. - Rapports techniques de M. Kanniche et al. (2015) [Source: EDF_2022-capitalisation-RO_Bore]. - Autres rapports de D. Bontemps et al. (2019) [Source: EDF_2022-capitalisation-RO_Bore]. Le Document 2 traite de la texturation des membranes et de la modélisation des phénomènes de transfert, mais ne cite pas d'auteur spécifique nommé Lee pour l'année 2022 [Source: Techniques séparatives sur membranes]. Par conséquent, je ne peux pas identifier le processus membranaire constituant la phase inverse du captage ni les mots-clés associés à cette étude spécifique, car ces informations ne sont pas présentes dans le corpus fourni. | F19: Le processus modélisé théoriquement est le stripping du CO2 (CO2 stripping). | L19: =IFERROR(AVERAGE(G19:K19),"")
A20: Q022 | B20: COMPARAISON | C20: N3 | D20: Dans quelles conditions obtient-on la teneur maximale en composé rapide au perméat d'un module de perméation gazeuse ? | E20: D'après les documents fournis, la teneur maximale en composé rapide au perméat d'un module de perméation gazeuse est obtenue dans un cas limite de fonctionnement, caractérisé par les conditions suivantes : 1. Force motrice maximale : La pression partielle du côté perméat est nulle, ce qui correspond à une force motrice maximale. * Mathématiquement : $\psi = 0$ [Source: 42493210-j2810-1]. * Cela implique que la pression du côté perméat est nulle ($p'' = 0$) [Source: 10 Chapitre Membranes Polycopié S6 ENSIC]. 2. Productivité minimale : Le taux de récupération du composé rapide est infiniment faible. * Mathématiquement : $\theta \sim 0$ [Source: 42493210-j2810-1]. * Cela correspond à un taux de prélèvement (stage cut) très faible [Source: 10 Chapitre Membranes Polycopié S6 ENSIC]. Conséquences et Limites : * Dans ces conditions, un enrichissement maximal en composé rapide au perméat est obtenu [Source: 42493210-j2810-1]. * Cependant, ces conditions sont décrites comme étant très éloignées de la réalité industrielle [Source: 42493210-j2810-1]. * Ce mode de fonctionnement peut s'apparenter à une colonne à distiller fonctionnant à reflux total, pour laquelle la teneur maximale en composé le plus volatil est obtenue au distillat [Source: 42493210-j2810-1]. Résumé des paramètres : Pour atteindre la valeur maximale de pureté au perméat ($y_{MAX}$), le module doit fonctionner avec : * $\psi = 0$ (Force motrice maximale) * $\theta \sim 0$ (Productivité minimale) Ces informations sont extraites des documents traitant des cas limites de perméation [Source: 42493210-j2810-1] et [Source: 10 Chapitre Membranes Polycopié S6 ENSIC]. | F20: Quand le stage cut ET le rapport de pression tendent tous les deux vers zéro simultanément — maximisant la force motrice locale sans appauvrir le rétentat. | L20: =IFERROR(AVERAGE(G20:K20),"")
A21: Q002 | B21: FACTUEL | C21: N1 | D21: Donner la signification des deux termes : Rétentat et Perméat. | E21: Basé sur les documents scientifiques fournis, voici la signification précise des termes Rétentat et Perméat dans le contexte des procédés de séparation membranaire. # 1. Perméat Le perméat correspond à la fraction du flux d'alimentation qui traverse la membrane sélective. * Définition : Il s'agit de la partie du flux qui passe à travers la membrane [Source: fndae14 | Page: 0]. * Composition : Il est exempt des molécules et/ou particules retenues par la membrane [Source: Techniques séparatives sur membranes | Page: 0]. Selon l'application, il peut être enrichi en un composé spécifique [Source: INPL_T_2003_MAUVIEL_G | Page: 0]. * Notation : Son débit est généralement noté $Q_p$ [Source: fndae14 | Page: 0]. * Positionnement : Il est obtenu du côté basse pression [Source: INPL_T_2003_MAUVIEL_G | Page: 0]. # 2. Rétentat Le rétentat correspond à la fraction du flux d'alimentation qui ne traverse pas la membrane. * Définition : C'est la partie restante du flux d'alimentation qui n'a pas traversé la membrane et qui reste dans la phase amont [Source: Thèse CIFRE Simon - 3 mars 2019 | Page: 0]. * Composition : Il contient les molécules ou particules retenues par la membrane [Source: fndae14 | Page: 0]. Il est également appelé concentrat [Source: Techniques séparatives sur membranes | Page: 0] ou flux résiduel [Source: INPL_T_2003_MAUVIEL_G | Page: 0]. * Notation : Son débit est généralement noté $Q_c$ [Source: fndae14 | Page: 0]. * Positionnement : Il est produit du côté haute pression [Source: INPL_T_2003_MAUVIEL_G | Page: 0]. # Action séparative La séparation est effective lorsque les compositions des flux au perméat et au rétentat sont différentes de celle du flux d'alimentation [Source: Thèse CIFRE Simon - 3 mars 2019 | Page: 0]. Selon l'application souhaitée, c'est soit le perméat, soit le rétentat qui représente le flux d'intérêt [Source: Thèse CIFRE Simon - 3 mars 2019 | Page: 0]. | F21: Rétentat : partie contenant les molécules ou particules retenues par la membrane. Perméat : partie contenant les molécules qui traversent la membrane. | L21: =IFERROR(AVERAGE(G21:K21),"")
A22: Q023 | B22: FACTUEL | C22: N2 | D22: Pour un matériau et une fraction molaire au perméat fixés, de quoi dépendent les performances d'un module de perméation gazeuse et l'épaisseur a-t-elle un rôle ? | E22: Il est important de préciser dès le départ qu'aucun document pertinent n'a été trouvé dans le corpus LRGP pour répondre spécifiquement à cette question. Par conséquent, je ne peux pas citer de source interne [Source: nom_article]. La réponse suivante est fournie sur la base de connaissances générales en génie des procédés membranaires. # Dépendances des performances d'un module de perméation Pour un matériau donné et une fraction molaire au perméat fixées, les performances d'un module de perméation gazeuse (définies généralement par le flux de perméation, la sélectivité et le taux de récupération) dépendent principalement des paramètres suivants : 1. La perméabilité du matériau ($P_i$) : C'est une propriété intrinsèque du polymère ou de la membrane céramique. Elle dépend de la solubilité ($S_i$) et de la diffusivité ($D_i$) du gaz dans la membrane selon la loi de solution-diffusion : $$P_i = S_i \times D_i$$ 2. La différence de pression partielle ($\Delta p_i$) : La force motrice du transfert de matière entre le côté alimentation (feed) et le côté perméat (perm). 3. La surface active de la membrane ($A$) : La surface totale des fibres creuses ou des membranes plates exposée au flux. 4. L'épaisseur de la membrane ($l$) : Elle joue un rôle critique, comme détaillé ci-dessous. 5. La température : Elle influence $D_i$ et $S_i$, modifiant ainsi $P_i$. # Rôle de l'épaisseur de la membrane L'épaisseur ($l$) a un rôle déterminant sur le flux de perméation, mais son effet sur la sélectivité est théoriquement nul dans le modèle idéal. Selon la loi de solution-diffusion, le flux molaire $J_i$ d'un gaz $i$ à travers une membrane est donné par l'équation suivante : $$J_i = \frac{P_i}{l} \times (p_{i,feed} - p_{i,perm})$$ Où : * $J_i$ est le flux molaire ($mol \cdot m^{-2} \cdot s^{-1}$). * $P_i$ est la perméabilité du matériau ($mol \cdot m \cdot m^{-2} \cdot s^{-1} \cdot Pa^{-1}$ ou $Barrer$). * $l$ est l'épaisseur de la membrane ($m$). * $p_{i,feed}$ e | F22: Dépendent du stage cut et du rapport de pression. L'épaisseur n'influence pas la sélectivité — elle impacte uniquement le flux de perméation global (loi solution-diffusion : J=P×Δp/l). | L22: =IFERROR(AVERAGE(G22:K22),"")
A23: Q075 | B23: FACTUEL | C23: N3 | D23: Quels sont les auteurs ayant historiquement proposé l'approche basée sur un coefficient global constant (Kov) dans les premières publications dédiées aux contacteurs membranaires ? | E23: D'après les documents fournis, l'approche de modélisation du transfert de matière dans les contacteurs membranaires basée sur un coefficient global constant ($K_{OV}$) a été historiquement proposée par les auteurs suivants dans les premières publications dédiées à ce domaine : * Bottino et al., 2008 * Qi et Cussler, 1985a et 1985b * Wickramasinghe et al., 1992 Cette liste d'auteurs est explicitement mentionnée dans les documents traitant de l'expression la plus simple pour la modélisation du transfert de matière dans les contacteurs membranaires [Source: CES 2012 revised manuscript_docx]. | F23: Cette approche a été historiquement proposée par Qi et Cussler (1985a, 1985b), Wickramasinghe et al. (1992), ainsi que Bottino et al. (2008). | L23: =IFERROR(AVERAGE(G23:K23),"")
A24: Q100 | B24: CALCUL | C24: N4 | D24: On modélise un contacteur membranaire avec l'approche du coefficient global constant Kov. La résistance globale (1/Kov) est de 2500 s/m. Sous une force motrice de concentration moyenne (ΔC) de 0,1 mol/m3, on souhaite capter 90 % du CO2 entrant (ratio ciblé dans les études du Doc 8). Si le débit d'entrée de CO2 est de 3,6 mol/s, et sachant que le flux de matière est J = Kov * ΔC, calculez l'aire membranaire totale (en m2) nécessaire (Débit capté = J * Aire). | F24: Kov = 1 / 2500 = 4.10^-4 m/s. Le flux transféré est J = 4.10^-4 * 0,1 = 4.10^-5 mol/(m2.s). La quantité de CO2 à capter est 3,6 * 0,90 = 3,24 mol/s. L'aire nécessaire est donc A = 3,24 / (4.10^-5) = 81000 m2. | L24: =IFERROR(AVERAGE(G24:K24),"")
A25: Q057 | B25: FACTUEL | C25: N2 | D25: Dans le modèle membranaire d'Ehsan Soroodan Miandoab, comment est défini le paramètre de configuration d'écoulement et en combien de cellules le module membranaire est-il divisé pour résoudre les équations de bilan de masse et d'énergie ? | E25: D'après les documents fournis dans le contexte, il est impossible de répondre précisément à votre question concernant le modèle membranaire d'Ehsan Soroodan Miandoab. Voici les éléments de réponse basés strictement sur les documents disponibles : 1. Absence de l'auteur spécifique : Les documents fournis (Document 1, Document 2, Document 3) ne mentionnent pas le nom "Ehsan Soroodan Miandoab" ni ne décrivent un modèle spécifique portant ce nom. 2. Description générique du module : Les documents décrivent un modèle générique où le module membranaire est divisé en $n$ cellules équivalentes ($1 \le j \le n$). La surface de chaque cellule ($\Delta S$) est définie comme la surface totale ($S$) divisée par le nombre total de cellules ($n$) : $$ \Delta S = \frac{S}{n} $$ [Source: (65_1) | Page: 0], [Source: 1-s2.0-S0376738816310742-main | Page: 0], [Source: Rigorous variable permeability modelling and process simulation for the design of polymeric membrane gas separation units MEMSIC simulation tool | Page: 0] 3. Paramètre de configuration d'écoulement : Aucun détail concernant un "paramètre de configuration d'écoulement" spécifique n'est fourni dans ces extraits. 4. Nombre de cellules : Le nombre de cellules est défini de manière symbolique par $n$, sans valeur numérique fixe indiquée dans le contexte. Conclusion : Je ne peux pas confirmer la définition du paramètre de configuration d'écoulement ni le nombre exact de cellules pour le modèle d'Ehsan Soroodan Miandoab, car ces informations ne sont pas présentes dans les documents fournis. Je ne peux pas inventer de valeurs ou d'auteurs en dehors du contexte autorisé. | F25: Le modèle membranaire opère en régime stationnaire en utilisant une configuration d'écoulement à contre-courant (counter-current flow configuration). Pour la résolution, le module membranaire est divisé en 100 cellules (100 cells). | L25: =IFERROR(AVERAGE(G25:K25),"")
A26: Q051 | B26: FACTUEL | C26: N2 | D26: Quel type spécifique de fibres creuses, caractérisé par son affinité avec l'eau et sa structure, est rapporté dans la littérature comme offrant des facteurs d'intensification impressionnants pour l'absorption du CO2 ? | E26: D'après les documents fournis dans le contexte, il n'est pas possible de répondre précisément à la question telle qu'elle est formulée. Analyse des documents : 1. Document 1 [Source: Modelling of Hollow Fibre Membrane Contactors - Application to Post-combustion Carbon Dioxide Capture, David Albarracin] : * Ce document mentionne que le contacteur membranaire à fibres creuses est une technologie permettant l'intensification des transferts gaz-liquide grâce à de grandes aires spécifiques et des coefficients de transfert élevés. * Il ne spécifie cependant aucun type de fibre particulier caractérisé par son affinité avec l'eau ni ne relie cette caractéristique à des facteurs d'intensification "impressionnants". 2. Document 2 [Source: 2011 NGUYEN_FAVRE Contacteurs à membranes denses pour les procédés d’absorption gaz-liquide intensifiés application à la capture du CO2 en post combustion] : * Ce document présente un tableau (Tableau I.14) listant des expériences bibliographiques. * Il mentionne des matériaux comme le PDMS, le PTFE, le PP, le PES. * Il cite des conditions telles que "Pas de mouillage" ou "Mouillage des fibres composites" (Falk-Pedersen et Dannström 1997). * Cependant, le texte ne précise pas qu'un type spécifique de fibres (par exemple, hydrophiles) offrant une affinité avec l'eau est rapporté comme offrant des facteurs d'intensification impressionnants. Conclusion : Les documents fournis ne contiennent pas l'information spécifique demandée concernant le type de fibres creuses caractérisé par son affinité avec l'eau et sa structure offrant des facteurs d'intensification impressionnants. Par conséquent, je ne peux pas identifier ce type de fibres sur la base exclusive des documents fournis. | F26: Il s'agit des fibres creuses microporeuses hydrophobes (hydrophobic microporous hollow fibers). | L26: =IFERROR(AVERAGE(G26:K26),"")
A27: Q029 | B27: FACTUEL | C27: N2 | D27: Dans l'étude de Lu et al. sur le captage du CO2 dans un contacteur de fibres creuses, quelles solutions ont été comparées et quelle conclusion en a été tirée concernant l'absorption ? | E27: D'après les documents fournis, voici les détails concernant l'étude de Lu et al. sur le captage du CO₂ : # 1. Solutions comparées Dans le cadre de l'examen de l'absorption à travers une membrane pour le captage de CO₂ dans un contacteur de fibres creuses de PP, deux solutions ont été employées pour absorber le CO₂ : * Une solution aqueuse de MDEA (Monoéthanolamine). * Une solution de MDEA activée avec PZ (Piperazine). [Source: Thèse_Molina_CO2 postcomb | Page: 0] # 2. Conclusion concernant l'absorption Les résultats de cette étude ont permis de tirer les conclusions suivantes : * Performance : L'absorption de CO₂ avec la MDEA activée était remarquablement plus élevée que celle obtenue avec la MDEA seule. * Applicabilité : L'utilisation d'un contacteur membranaire avec des alcanolamines telles que la MDEA activée avec PZ peut être complètement appliquée au captage du CO₂. [Source: Thèse_Molina_CO2 postcomb | Page: 0] *(Note : Le même texte est également présent dans le document [Source: Comparaison du captage du CO2 en postcomb par des solutions d’ammoniaque et d’amines organiques - Évaluation en contacteurs, approches cinétiques, thermo et modélisation_MOLINA | Page: 0].)* | F27: Deux solutions ont été comparées : une solution aqueuse de MDEA seule et une solution de MDEA activée avec de la pipérazine (PZ). Les résultats ont montré que l'absorption de CO2 avec la MDEA activée (MDEA + PZ) était remarquablement plus élevée que celle avec la MDEA seule. | L27: =IFERROR(AVERAGE(G27:K27),"")
A28: Q019 | B28: FACTUEL | C28: N1 | D28: Quels types de matériaux et structures sont employés pour réaliser une séparation membranaire ? | E28: D'après les documents fournis, les matériaux et structures employés pour réaliser une séparation membranaire peuvent être classés selon leur nature chimique, leur porosité et leur mécanisme de séparation. Voici une synthèse structurée : # 1. Membranes Polymères Denses Ces membranes sont constituées d'une couche dense (skin) polymère. * Matériaux spécifiques : Les plastiques utilisés sont particulièrement préférés, notamment les polyimides, polyamides, polysulphones, cellulose acetates et dérivés, polyphenylene oxides, polysiloxanes, polyethylene oxides, polypropylene oxides [Source: US2014345457A1_Original_document_20210719110036]. * Mécanisme : Le mécanisme de séparation repose sur la solution-diffusion [Source: ogst130021]. * Propriétés : Ces matériaux doivent offrir des perméances et sélectivités adéquates, ainsi qu'une stabilité mécanique, thermique et chimique [Source: 36587495]. # 2. Membranes Inorganiques et Microporeuses Ces structures sont basées sur des matériaux non polymères. * Matériaux : Silice, carbone (membranes céramiques ou CMSMs), zéolites [Source: 1-s2.0-S1876610217319549-main], [Source: US2014345457A1_Original_document_20210719110036], [Source: ogst130021]. * Structures : * Membranes microporeuses inorganiques : Le diamètre des pores est compris entre le diamètre cinétique des perméants et le libre parcours moyen [Source: ogst130021]. * Membranes tamis moléculaire (Zeolite) : Le diamètre des pores est proche ou inférieur au diamètre cinétique des molécules [Source: ogst130021]. * Mécanismes : * Écoulement de Knudsen (pour les membranes microporeuses inorganiques) [Source: ogst130021]. * Tamisage moléculaire (pour les zéolites) [Source: ogst130021]. # 3. Membranes Hybrides et Structures Avancées Ces structures combinent différentes phases ou mécanismes pour améliorer les performances. * Membranes Matrices Mixtes (MMMs) : Composées d'une phase polymère continue avec des particules inorganiques adsorbantes d | F28: Matériaux organiques (polymères) ou inorganiques (céramiques, métaux). Structures poreuses (micro/ultrafiltration) ou denses (osmose inverse, perméation gazeuse). | L28: =IFERROR(AVERAGE(G28:K28),"")
A29: Q068 | B29: FACTUEL | C29: N2 | D29: Dans le tableau 2 présentant les caractéristiques de transport des gaz, quelles sont les perméabilités respectives (en mélange) pour le méthane (CH4), le propane (C3H8) et le n-butane (nC4H10) à travers la membrane en PDMS ? | E29: D'après les documents fournis, les informations concernant le Tableau 2 sont extraites du Document 2. Ce document liste explicitement les coefficients de perméabilité en mélange pour la membrane en PDMS. Voici les perméabilités respectives (en mélange) pour les gaz demandés à travers la membrane en PDMS, telles que reportées dans le Tableau 2 : * Méthane (CH₄) : $700 \text{ Barrer}$ * Propane (C₃H₈) : $2440 \text{ Barrer}$ * n-Butane (nC₄H₁₀) : $5300 \text{ Barrer}$ Ces valeurs correspondent aux coefficients de perméabilité dans le mélange gazeux pour la membrane PDMS. [Source: 1-s2.0-S1383586619350348-main] | F29: Les perméabilités en mélange à travers le PDMS sont : CH4 = 700 Barrer ; C3H8 = 2440 Barrer ; nC4H10 = 5300 Barrer. | L29: =IFERROR(AVERAGE(G29:K29),"")
A30: Q011 | B30: CALCUL | C30: N4 | D30: Épuration eau (0,09 kg phénol/m³, V=4 m³), 2 kg charbon actif, dp=250 µm, 15°C. Isotherme Langmuir : m=C/(5,13×10⁻³C+4,06×10⁻²). kcpap=0,2×10⁻⁴ s⁻¹. Déterminer R, la concentration limite et la durée pour atteindre 0,009 kg/m³. | F30: R=0,989. Concentration limite C=0,0068 kg/m³. Durée t=13 740 s ≈ 3,82 h. | L30: =IFERROR(AVERAGE(G30:K30),"")
A31: Q021 | B31: FACTUEL | C31: N2 | D31: De quels paramètres dépendent les performances de séparation d'un module de perméation gazeuse ? | E31: D'après les documents fournis, les performances de séparation d'un module de perméation gazeuse dépendent de plusieurs paramètres distincts, classés ci-dessous : # 1. Propriétés intrinsèques du matériau membranaire L'efficacité de l'opération de séparation dépend logiquement des performances du matériau membranaire lui-même. Selon le document [Source: 10 Chapitre Membranes Polycopié S6 ENSIC], ces performances sont caractérisées par : * La perméabilité. * La permselectivité. # 2. Conditions opératoires et force motrice Les performances dépendent également des conditions physiques appliquées au module. Le document [Source: 10 Chapitre Membranes Polycopié S6 ENSIC] précise que cela inclut : * La force motrice appliquée, définie comme la différence de pression partielle de part et d'autre de la membrane pour les différents composés. * Les pressions amont et aval (notées $p_i'$ et $p_{te}''$ dans le document [Source: DDOC_T_2017_0020_PFISTER]). * L'énergie consommée à chaque étage [Source: DDOC_T_2017_0020_PFISTER]. # 3. Agencement et variables de procédé L'agencement des flux dans le module est un paramètre déterminant cité explicitement [Source: 10 Chapitre Membranes Polycopié S6 ENSIC]. De plus, le document [Source: DDOC_T_2017_0020_PFISTER] identifie d'autres variables influençant l'estimation des performances : * Les taux de récupération (notés $R_{CO2}$). * La fraction en CO₂ intermédiaire (notée $y_{1CO2}$). * Les performances de séparation des membranes (cas 1, 2 ou 3). # 4. Nature du procédé Il est important de noter que, contrairement à la distillation ou à l'absorption, la séparation par perméation gazeuse est un procédé cinétique [Source: 42331210-j2810], [Source: Technique_Ingenieur], [Source: Techniques séparatives sur membranes]. Elle est basée sur les différences des vitesses de perméation à travers une membrane des constituants d'un mélange gazeux. *Note : Les documents [Source: 42331210-j2810], [Source: Technique_Ingenieur] et [Sou | F31: Sélectivité du matériau membranaire, rapport de pression amont/aval, taux de prélèvement (stage cut). Pas de dépendance à une courbe d'équilibre thermodynamique. | L31: =IFERROR(AVERAGE(G31:K31),"")
A32: Q091 | B32: CALCUL | C32: N3 | D32: Dindore et al. (2004) ont étudié l'absorption du CO2 à des pressions élevées (elevated pressures, Doc 7). Pour une absorption dans un contacteur à fibres creuses opérant à une pression totale de 15 bar (soit 1500 kPa), la fraction molaire du CO2 dans la phase gaz est de 30 %. En supposant un comportement de gaz parfait et une température opératoire de 300 K (avec R = 8,314 J/(mol.K)), calculez la concentration de CO2 dans la phase gazeuse (en mol/m3) disponible pour le transfert interfaciel. | F32: La pression partielle de CO2 est P_CO2 = 0,30 * 1500 kPa = 450 kPa = 450 000 Pa. En appliquant la loi des gaz parfaits (C = P/RT), la concentration est C_g = 450 000 / (8,314 * 300) = 450 000 / 2494,2 = 180,4 mol/m3. | L32: =IFERROR(AVERAGE(G32:K32),"")
A33: Q016 | B33: CALCUL | C33: N3 | D33: À 25°C, une membrane d'osmose inverse est utilisée pour une solution d'alimentation en NaCl contenant 2,5 g/L (2,5 kg/m³, ρ = 999 kg/m³). La constante de perméabilité à l'eau est Aw = 4,81 × 10⁻⁴ kg/(s·m²·atm) et la constante de perméabilité du soluté est As = 4,42 × 10⁻⁷ m/s. Calculer le flux d'eau (Nw), le flux de soluté (Ns), la rétention R et la concentration C2 du perméat. Donnée : ΔP = 27,20 atm. | E33: # Analyse de la demande de calcul Je dois vous informer d'une limitation importante concernant votre demande de calcul. 1. Équations nécessaires non disponibles dans le contexte Après examen attentif des documents fournis, aucune équation de calcul pour le flux d'eau (Nw) ou le flux de soluté (Ns) en osmose inverse n'est présente dans les documents du corpus LRGP. Les documents contiennent : - [Source: Thèse CIFRE Simon - 3 mars 2019 | Page: 0] : Classification des technologies membranaires sans équations de flux - [Source: fndae14 | Page: 0] : Taux de rejet au NaCl sans équations de calcul - [Source: 1-s2.0-S0304386X20304539-main | Page: 0] : Figure sans équations - [Source: 1-s2.0-S2214714419311341-main | Page: 0] : Mention de la perméabilité A évaluée par tests RO, mais sans équation - [Source: Dupont-XUS180808-L | Page: 0] : Conditions de test sans équations 2. Données disponibles dans le contexte Les documents mentionnent : - [Source: fndae14 | Page: 0] : Taux de rejet au NaCl de 99 % pour le dessalement d'eau de mer - [Source: fndae14 | Page: 0] : Taux de rejet au NaCl de 96 % pour les eaux saumâtres - [Source: Dupont-XUS180808-L | Page: 0] : Conditions de test (32 000 ppm NaCl, 800 psi, 25°C, pH 8, 8% recovery) 3. Informations manquantes pour le calcul Pour effectuer ce calcul, il manque dans le contexte : - L'équation de calcul du flux d'eau (généralement $J_w = A_w(\Delta P - \Delta \pi)$) - L'équation de calcul du flux de soluté (généralement $J_s = A_s \Delta C$) - La pression osmotique $\Delta \pi$ - La concentration du perméat $C_2$ 4. Conclusion Je ne peux pas effectuer ce calcul car les équations nécessaires ne sont pas fournies dans les documents du corpus LRGP. Pour obtenir ces équations, je vous recommande de consulter : - La littérature scientifique sur les membranes d'osmose inverse - Les spécifications techniques des membranes (comme mentionné dans [Source: Dupont-XUS180808-L | Page: 0]) - Les documents techniques des fabricants d | F33: 1) Pression osmotique de l'alimentation : π1 = i·(C1/M)·R·T = 2 × (2,5 / 58,45) × 0,08206 × 298,15 = 2,093 atm. 2) Paramètre B = Aw / (As × ρ) = 4,81·10⁻⁴ / (4,42·10⁻⁷ × 999) = 1,089 atm⁻¹. 3) Par itération avec R = B(ΔP - Δπ) / [1 + B(ΔP - Δπ)], on converge rapidement vers R = 0,965 (soit 96,5 %). 4) Concentration du perméat : C2 = C1(1 - R) = 2,5 × (1 - 0,965) = 0,088 kg/m³. 5) Différence de pression osmotique : π2 = π1 × (C2/C1) = 0,074 atm, d'où Δπ = 2,093 - 0,074 = 2,019 atm. 6) Flux d'eau : Nw = Aw(ΔP - Δπ) = 4,81·10⁻⁴ × (27,20 - 2,019) = 1,21·10⁻² kg/(m²·s). 7) Flux de soluté : Ns = As(C1 - C2) = 4,42·10⁻⁷ × (2,5 - 0,088) = 1,06·10⁻⁶ kg/(m²·s). | L33: =IFERROR(AVERAGE(G33:K33),"")
A34: Q071 | B34: FACTUEL | C34: N2 | D34: Quel paramètre unique permet d'évaluer rapidement et facilement les performances du procédé de transfert de matière dans un contacteur membranaire selon les premières publications ? | E34: Selon les documents fournis, le paramètre unique permettant d'évaluer rapidement et facilement les performances du procédé de transfert de matière dans un contacteur membranaire est le coefficient de transfert de matière global, noté $K_{OV}$. Voici les détails basés sur les documents : 1. Identification du paramètre : L'approche la plus simple pour la modélisation du transfert de matière dans un contacteur membranaire repose sur un coefficient de transfert de matière global constant, $K_{OV}$ [Source: CES 2012 revised manuscript_docx]. 2. Raison de ce choix : Cette approche a l'avantage d'inclure les différents mécanismes de transfert de matière dans un seul paramètre global ($K_{OV}$), ce qui permet d'évaluer rapidement les performances du procédé [Source: CES 2012 revised manuscript_docx]. 3. Comparaison et évaluation : Connaître la surface interfaciale gaz-liquide ($a$) et le coefficient global ($K_{OV}$) permet d'obtenir facilement la performance $K_{OV} \cdot a$ et de la comparer avec d'autres technologies [Source: Elsevier Encyclopedia Membrane Contactors Chabanon & Favre]. Conclusion : Le paramètre clé est donc $K_{OV}$ (coefficient de transfert de matière global), car il regroupe les mécanismes de transfert et simplifie l'évaluation des performances [Source: CES 2012 revised manuscript_docx ; Source: Elsevier Encyclopedia Membrane Contactors Chabanon & Favre]. | F34: L'évaluation est basée sur l'utilisation d'un paramètre unique : le coefficient global de transfert de matière constant, noté Kov. | L34: =IFERROR(AVERAGE(G34:K34),"")
A35: Q063 | B35: FACTUEL | C35: N1 | D35: Quel est le mécanisme régissant le transport des composés à travers les membranes denses en polymère (comme pour la perméation gazeuse ou la pervaporation) et quelle relation relie la perméabilité à la solubilité et à la diffusion ? | E35: D'après les documents fournis dans le contexte, voici la réponse structurée concernant le transport à travers les membranes denses en polymère. # 1. Mécanisme de transport Le transport des molécules gazeuses à travers les membranes denses en polymère est régi par le mécanisme solution-diffusion [Source: DDOC_T_2017_0020_PFISTER]. Ce mécanisme se déroule en deux étapes séquentielles : 1. Dissolution : Les molécules de gaz se dissolvent d'abord dans la membrane polymère dense. 2. Diffusion : Les molécules diffusent ensuite à travers la membrane [Source: DDOC_T_2017_0020_PFISTER]. # 2. Relation entre Perméabilité, Solubilité et Diffusivité La perméabilité ($P$) d'un polymère est définie comme le produit de la diffusivité ($D$) et de la solubilité ($S$) [Source: sterescu-et-al-2006-fullerene-modified-poly(2-6-dimethyl-1-4-phenylene-oxide)-gas-separation-membranes-why-binding-is]. La relation mathématique est exprimée par l'équation suivante : $$P = D \times S$$ Où : * $P$ représente la perméabilité (compromis entre la vitesse de transport et la capacité de rétention). * $D$ représente la diffusivité, correspondant au composant cinétique du transport [Source: sterescu-et-al-2006-fullerene-modified-poly(2-6-dimethyl-1-4-phenylene-oxide)-gas-separation-membranes-why-binding-is]. * $S$ représente la solubilité, correspondant au composant thermodynamique du transport [Source: sterescu-et-al-2006-fullerene-modified-poly(2-6-dimethyl-1-4-phenylene-oxide)-gas-separation-membranes-why-binding-is]. Cette description repose sur la loi de Fick avec l'hypothèse d'un coefficient de diffusion constant [Source: DDOC_T_2017_0020_PFISTER]. | F35: Le mécanisme de transport est le mécanisme de solution-diffusion. La perméabilité (P) est définie comme le produit de la solubilité (S) et du coefficient de diffusion (D), soit l'équation : P = S · D. | L35: =IFERROR(AVERAGE(G35:K35),"")
A36: Q038 | B36: COMPARAISON | C36: N2 | D36: Quels sont les deux procédés membranaires fondamentalement distincts étudiés pour l'élimination efficace du CO2 contenu dans le CH4 ? | E36: D'après les documents fournis, la thèse de K. Simons examine le potentiel de la technologie membranaire pour l'élimination efficace du CO₂ contenu dans le CH₄. L'étude se concentre sur deux procédés membranaires fondamentalement distincts pour accomplir cette séparation [Source: thesis_K_Simons]. Ces deux procédés sont : 1. L'utilisation d'un contacteur membrane gaz-liquide : Ce procédé est dédié à l'absorption sélective du CO₂ à partir du mélange CH₄ [Source: thesis_K_Simons]. 2. L'utilisation de membranes de séparation gazeuse fines et denses : Ce procédé est utilisé pour établir la séparation par séparation directe des gaz [Source: thesis_K_Simons]. Détails complémentaires sur la répartition des chapitres : * Le premier procédé (contacteur gaz-liquide) est principalement décrit dans les chapitres 2 à 4, qui se concentrent sur les aspects technologiques du procédé et la conception du système [Source: thesis_K_Simons]. * Le second procédé (membranes fines et denses) est décrit dans les chapitres 5 et 6, dont le focus est principalement sur le développement de nouveaux matériaux membranaires pour la séparation du CO₂ [Source: thesis_K_Simons]. | F36: Les deux procédés sont : 1) l'utilisation d'un contacteur membranaire gaz-liquide pour l'absorption sélective du CO2 à partir du CH4, et 2) l'utilisation de membranes denses et fines de séparation de gaz (gas separation membranes). | L36: =IFERROR(AVERAGE(G36:K36),"")
